---
title: 无法获取报错信息的问题总结
date: 2021-05-04 22:40:42
tags:
  - ES6
  - Promise
---
这次“无法获取报错信息”的问题，经过排查总结，是由 Promise 对象使用不当引起的，因此我们先回顾一下 Promise 对象的使用。

# Promise对象的使用

## Promise对象

```js
// 创造Promise对象实例
const promise = new Promise(function(resolve, reject) {
  // ... some code
	// 在内部设定异步操作成功/失败的判断条件
  if (/* 异步操作成功 */){
    resolve(value);
  } else {
    reject(error);
  }
});
```

## then()方法

调用`resolve`或`reject`以后，Promise 的使命就完成了，后继操作应该放到`then`方法里面。我们用`then`指定异步操作成功为`resolved`状态和失败`rejected`状态的回调函数。

```js
promise.then(function(value) {
  // success
}, function(error) {
  // failure
});
```

这里的`value`和`error`其实是同一个东西，都是`Promise`对象传出的值。只是如果操作成功，值就会被传给第一个回调函数；操作失败，值会被传给第二个回调函数。

## catch()方法

如果异步操作抛出错误，状态就会变为`rejected`，就会调用`catch()`方法指定的回调函数，处理这个错误。

```js
promise
.then((value)=>{}, (error)=>{})
.catch((error)=>{})
```

既然可以在`then`中指定操作失败的回调函数（`then`的第二个参数），那么为什么又需要`catch`呢？

`reject()`方法的作用，其实就等同于抛出错误。一般来说，我们不在`then()`方法里面定义 Reject 状态的回调函数（即`then`的第二个参数），而总是使用`catch`方法。

并且，`catch`还有另外一个作用：它不仅能捕获`Promise`的错误，也能捕获`then`的错误。如果没有使用`catch()`方法指定错误处理的回调函数，`Promise对象`抛出的错误不会传递到外层代码，即不会有任何反应。

## then()的回调函数

`then()`接受的两个回调函数，是可选的，即你可以不设置回调函数。如果不设置回调函数，会发生什么呢？用我们自己的代码举例：

- 不使用`then`设置回调函数

```js
// request.js
const request = (data) => {
	return new Promise((resolve, reject) => {
    // ... some code
    if(res.data.code === 0 || res.data.code == 200) resolve(res.data)
    else reject(res.data)
  })
};
// app.js
async globalRequest(data) {
  let result = await requestFunc.request(data)
  // 原本应接着写.then(()=>{})
 }
```

结果是`result`即为`resolve(res.data)`中拿到的`res.data`，这意味着，我们不指定回调函数时，会默认返回`resolve()`拿到的值。

- 设置`then`中Resolved状态的回调函数（即第一个参数）

```js
async globalRequest(data) {
    let result = await requestFunc.request(data)
    .then((value)=>{
      // 只打印拿到的值，不return value
    console.log(value)
    })
  }
```

结果便是打印了`res.data`，`result`为`undefined`，因为我们没有将值返回。

- 不设置`then`中Rejected状态的回调函数（即第二个参数）

代码同上，异步操作成功，不会报错；异步操作失败，由于没有对`reject()`做任何后续处理，所以外部也接受不到任何信息。

#  问题代码复现

1. 我们在`request.js`中创造了Promise对象实例，并根据返回的状态码来判定异步操作是否成功。

```js
const request = (data) => {
	return new Promise( (resolve, reject) => {
		wx.request({
			// ... some code
			success (res) {
					if(res.data.code === 0 || res.data.code == 200) resolve(res.data)
					else reject(res.data)
				}
		})
	});
}
```

2. 我们在`app.js`中拿到`request`返回的值。

```js
async globalRequest(data) {
		let result = await requestFunc.request(data);
    // ... some code
		if (res.code != 0 && res.code != 200){ 
    // ... some code
    }
    return res;
  }
```

所有请求成功（`res.data.code === 0 || res.data.code == 200`）的情况下，`res.data`都会被赋值给`app.js`中的`result`。（未指定回调函数时，默认返回`resolve()`拿到的值）。

在`app.js`中，根本不会存在`res.code != 0`或是`res.code ！= 200`的情况，因为这种情况已经在`request.js`中被判定为异步操作失败而将错误信息传给`reject()`了。

为什么单页面中拿不到报错信息？因为我们没有通过`catch()`去捕获及处理错误信息。

# 解决方法

要捕获错误信息，并作出相应处理，就要使用`catch()`方法。

```js
	async globalRequest(data) {
    let result = await requestFunc.request(data)
    //  使用catch()方法捕获错误
    .catch((error) => {
 		// ... 作出相应的处理
      })
    })
    return result
  }
```

# 参考阅读

[Promise对象](https://es6.ruanyifeng.com/#docs/promise)

